{"name": "Class CertPathValidatorException", "module": "java.base", "package": "java.security.cert", "text": "An exception indicating one of a variety of problems encountered when\n validating a certification path.\n \n A CertPathValidatorException provides support for wrapping\n exceptions. The getCause method returns the throwable,\n if any, that caused this exception to be thrown.\n \n A CertPathValidatorException may also include the\n certification path that was being validated when the exception was thrown,\n the index of the certificate in the certification path that caused the\n exception to be thrown, and the reason that caused the failure. Use the\n getCertPath, getIndex, and\n getReason methods to retrieve this information.\n\n \nConcurrent Access\n\n Unless otherwise specified, the methods defined in this class are not\n thread-safe. Multiple threads that need to access a single\n object concurrently should synchronize amongst themselves and\n provide the necessary locking. Multiple threads each manipulating\n separate objects need not synchronize.", "codes": ["public class CertPathValidatorException\nextends GeneralSecurityException"], "fields": [], "methods": [{"method_name": "getCertPath", "method_sig": "public CertPath getCertPath()", "description": "Returns the certification path that was being validated when\n the exception was thrown."}, {"method_name": "getIndex", "method_sig": "public int getIndex()", "description": "Returns the index of the certificate in the certification path\n that caused the exception to be thrown. Note that the list of\n certificates in a CertPath is zero based. If no\n index has been set, -1 is returned."}, {"method_name": "getReason", "method_sig": "public CertPathValidatorException.Reason getReason()", "description": "Returns the reason that the validation failed. The reason is\n associated with the index of the certificate returned by\n getIndex()."}]}